*** Starting uWSGI 2.0.30 (64bit) on [Sun Aug 10 10:30:13 2025] ***
compiled with version: 12.2.0 on 10 August 2025 08:55:24
os: Linux-5.15.167.4-microsoft-standard-WSL2 #1 SMP Tue Nov 5 00:21:55 UTC 2024
nodename: c59b46171162
machine: x86_64
clock source: unix
pcre jit disabled
detected number of CPU cores: 8
current working directory: /code
detected binary path: /usr/local/bin/uwsgi
uWSGI running as root, you can use --uid/--gid/--chroot options
*** WARNING: you are running uWSGI as root !!! (use the --uid flag) *** 
your memory page size is 4096 bytes
detected max file descriptor number: 1024
lock engine: pthread robust mutexes
thunder lock: disabled (you can enable it with --thunder-lock)
uwsgi socket 0 bound to TCP address :8001 fd 3
uWSGI running as root, you can use --uid/--gid/--chroot options
*** WARNING: you are running uWSGI as root !!! (use the --uid flag) *** 
Python version: 3.7.17 (default, Sep 20 2023, 11:53:41)  [GCC 12.2.0]
Python main interpreter initialized at 0x557977f1a150
uWSGI running as root, you can use --uid/--gid/--chroot options
*** WARNING: you are running uWSGI as root !!! (use the --uid flag) *** 
python threads support enabled
your server socket listen backlog is limited to 100 connections
your mercy for graceful operations on workers is 60 seconds
mapped 145840 bytes (142 KB) for 1 cores
*** Operational MODE: single process ***
WSGI app 0 (mountpoint='') ready in 1 seconds on interpreter 0x557977f1a150 pid: 1 (default app)
mountpoint  already configured. skip.
uWSGI running as root, you can use --uid/--gid/--chroot options
*** WARNING: you are running uWSGI as root !!! (use the --uid flag) *** 
*** uWSGI is running in multiple interpreter mode ***
spawned uWSGI master process (pid: 1)
spawned uWSGI worker 1 (pid: 7, cores: 1)
Python auto-reloader enabled
[pid: 7|app: 0|req: 1/1] 172.20.0.1 () {54 vars in 973 bytes} [Sun Aug 10 10:30:43 2025] GET / => generated 10697 bytes in 30 msecs (HTTP/1.1 200) 5 headers in 153 bytes (1 switches on core 0)
Not Found: /favicon.ico
[pid: 7|app: 0|req: 2/2] 172.20.0.1 () {52 vars in 905 bytes} [Sun Aug 10 10:30:43 2025] GET /favicon.ico => generated 2115 bytes in 11 msecs (HTTP/1.1 404) 5 headers in 159 bytes (1 switches on core 0)
[uwsgi-python-reloader] module/file ./mainproject/urls.py has been modified
...gracefully killing workers...
Gracefully killing worker 1 (pid: 7)...
worker 1 buried after 2 seconds
binary reloading uWSGI...
chdir() to /code
closing all non-uwsgi socket fds > 2 (max_fd = 1024)...
found fd 3 mapped to socket 0 (:8001)
running /usr/local/bin/uwsgi
[uWSGI] getting INI configuration from /code/mainproject/django.ini
*** Starting uWSGI 2.0.30 (64bit) on [Sun Aug 10 11:00:55 2025] ***
compiled with version: 12.2.0 on 10 August 2025 08:55:24
os: Linux-5.15.167.4-microsoft-standard-WSL2 #1 SMP Tue Nov 5 00:21:55 UTC 2024
nodename: c59b46171162
machine: x86_64
clock source: unix
pcre jit disabled
detected number of CPU cores: 8
current working directory: /code
detected binary path: /usr/local/bin/uwsgi
uWSGI running as root, you can use --uid/--gid/--chroot options
*** WARNING: you are running uWSGI as root !!! (use the --uid flag) *** 
your memory page size is 4096 bytes
detected max file descriptor number: 1024
lock engine: pthread robust mutexes
thunder lock: disabled (you can enable it with --thunder-lock)
uwsgi socket 0 inherited INET address :8001 fd 3
uWSGI running as root, you can use --uid/--gid/--chroot options
*** WARNING: you are running uWSGI as root !!! (use the --uid flag) *** 
Python version: 3.7.17 (default, Sep 20 2023, 11:53:41)  [GCC 12.2.0]
Python main interpreter initialized at 0x55b661fff130
uWSGI running as root, you can use --uid/--gid/--chroot options
*** WARNING: you are running uWSGI as root !!! (use the --uid flag) *** 
python threads support enabled
your server socket listen backlog is limited to 100 connections
your mercy for graceful operations on workers is 60 seconds
mapped 145840 bytes (142 KB) for 1 cores
*** Operational MODE: single process ***
WSGI app 0 (mountpoint='') ready in 1 seconds on interpreter 0x55b661fff130 pid: 1 (default app)
mountpoint  already configured. skip.
uWSGI running as root, you can use --uid/--gid/--chroot options
*** WARNING: you are running uWSGI as root !!! (use the --uid flag) *** 
*** uWSGI is running in multiple interpreter mode ***
gracefully (RE)spawned uWSGI master process (pid: 1)
spawned uWSGI worker 1 (pid: 9, cores: 1)
Python auto-reloader enabled
Internal Server Error: /
Traceback (most recent call last):
  File "/usr/local/lib/python3.7/site-packages/django/core/handlers/exception.py", line 47, in inner
    response = get_response(request)
  File "/usr/local/lib/python3.7/site-packages/django/core/handlers/base.py", line 167, in _get_response
    callback, callback_args, callback_kwargs = self.resolve_request(request)
  File "/usr/local/lib/python3.7/site-packages/django/core/handlers/base.py", line 290, in resolve_request
    resolver_match = resolver.resolve(request.path_info)
  File "/usr/local/lib/python3.7/site-packages/django/urls/resolvers.py", line 560, in resolve
    for pattern in self.url_patterns:
  File "/usr/local/lib/python3.7/site-packages/django/utils/functional.py", line 48, in __get__
    res = instance.__dict__[self.name] = self.func(instance)
  File "/usr/local/lib/python3.7/site-packages/django/urls/resolvers.py", line 602, in url_patterns
    patterns = getattr(self.urlconf_module, "urlpatterns", self.urlconf_module)
  File "/usr/local/lib/python3.7/site-packages/django/utils/functional.py", line 48, in __get__
    res = instance.__dict__[self.name] = self.func(instance)
  File "/usr/local/lib/python3.7/site-packages/django/urls/resolvers.py", line 595, in urlconf_module
    return import_module(self.urlconf_name)
  File "/usr/local/lib/python3.7/importlib/__init__.py", line 127, in import_module
    return _bootstrap._gcd_import(name[level:], package, level)
  File "<frozen importlib._bootstrap>", line 1006, in _gcd_import
  File "<frozen importlib._bootstrap>", line 983, in _find_and_load
  File "<frozen importlib._bootstrap>", line 967, in _find_and_load_unlocked
  File "<frozen importlib._bootstrap>", line 677, in _load_unlocked
  File "<frozen importlib._bootstrap_external>", line 728, in exec_module
  File "<frozen importlib._bootstrap>", line 219, in _call_with_frames_removed
  File "./mainproject/urls.py", line 21, in <module>
    path('app/', include('app.urls')),
  File "/usr/local/lib/python3.7/site-packages/django/urls/conf.py", line 34, in include
    urlconf_module = import_module(urlconf_module)
  File "/usr/local/lib/python3.7/importlib/__init__.py", line 127, in import_module
    return _bootstrap._gcd_import(name[level:], package, level)
  File "<frozen importlib._bootstrap>", line 1006, in _gcd_import
  File "<frozen importlib._bootstrap>", line 983, in _find_and_load
  File "<frozen importlib._bootstrap>", line 967, in _find_and_load_unlocked
  File "<frozen importlib._bootstrap>", line 677, in _load_unlocked
  File "<frozen importlib._bootstrap_external>", line 728, in exec_module
  File "<frozen importlib._bootstrap>", line 219, in _call_with_frames_removed
  File "./app/urls.py", line 1, in <module>
    from djago.urls import path
ModuleNotFoundError: No module named 'djago'
[pid: 9|app: 0|req: 1/1] 172.20.0.1 () {54 vars in 973 bytes} [Sun Aug 10 11:01:24 2025] GET / => generated 142741 bytes in 195 msecs (HTTP/1.1 500) 6 headers in 187 bytes (1 switches on core 0)
[uwsgi-python-reloader] module/file ./mainproject/settings.py has been modified
...gracefully killing workers...
Gracefully killing worker 1 (pid: 9)...
worker 1 buried after 1 seconds
binary reloading uWSGI...
chdir() to /code
closing all non-uwsgi socket fds > 2 (max_fd = 1024)...
found fd 3 mapped to socket 0 (:8001)
running /usr/local/bin/uwsgi
[uWSGI] getting INI configuration from /code/mainproject/django.ini
*** Starting uWSGI 2.0.30 (64bit) on [Sun Aug 10 11:02:04 2025] ***
compiled with version: 12.2.0 on 10 August 2025 08:55:24
os: Linux-5.15.167.4-microsoft-standard-WSL2 #1 SMP Tue Nov 5 00:21:55 UTC 2024
nodename: c59b46171162
machine: x86_64
clock source: unix
pcre jit disabled
detected number of CPU cores: 8
current working directory: /code
detected binary path: /usr/local/bin/uwsgi
uWSGI running as root, you can use --uid/--gid/--chroot options
*** WARNING: you are running uWSGI as root !!! (use the --uid flag) *** 
your memory page size is 4096 bytes
detected max file descriptor number: 1024
lock engine: pthread robust mutexes
thunder lock: disabled (you can enable it with --thunder-lock)
uwsgi socket 0 inherited INET address :8001 fd 3
uWSGI running as root, you can use --uid/--gid/--chroot options
*** WARNING: you are running uWSGI as root !!! (use the --uid flag) *** 
Python version: 3.7.17 (default, Sep 20 2023, 11:53:41)  [GCC 12.2.0]
Python main interpreter initialized at 0x564704e03130
uWSGI running as root, you can use --uid/--gid/--chroot options
*** WARNING: you are running uWSGI as root !!! (use the --uid flag) *** 
python threads support enabled
your server socket listen backlog is limited to 100 connections
your mercy for graceful operations on workers is 60 seconds
mapped 145840 bytes (142 KB) for 1 cores
*** Operational MODE: single process ***
WSGI app 0 (mountpoint='') ready in 0 seconds on interpreter 0x564704e03130 pid: 1 (default app)
mountpoint  already configured. skip.
uWSGI running as root, you can use --uid/--gid/--chroot options
*** WARNING: you are running uWSGI as root !!! (use the --uid flag) *** 
*** uWSGI is running in multiple interpreter mode ***
gracefully (RE)spawned uWSGI master process (pid: 1)
spawned uWSGI worker 1 (pid: 11, cores: 1)
Python auto-reloader enabled
Traceback (most recent call last):
  File "/usr/local/lib/python3.7/site-packages/django/core/handlers/exception.py", line 47, in inner
    response = get_response(request)
  File "/usr/local/lib/python3.7/site-packages/django/core/handlers/base.py", line 167, in _get_response
    callback, callback_args, callback_kwargs = self.resolve_request(request)
  File "/usr/local/lib/python3.7/site-packages/django/core/handlers/base.py", line 290, in resolve_request
    resolver_match = resolver.resolve(request.path_info)
  File "/usr/local/lib/python3.7/site-packages/django/urls/resolvers.py", line 560, in resolve
    for pattern in self.url_patterns:
  File "/usr/local/lib/python3.7/site-packages/django/utils/functional.py", line 48, in __get__
    res = instance.__dict__[self.name] = self.func(instance)
  File "/usr/local/lib/python3.7/site-packages/django/urls/resolvers.py", line 602, in url_patterns
    patterns = getattr(self.urlconf_module, "urlpatterns", self.urlconf_module)
  File "/usr/local/lib/python3.7/site-packages/django/utils/functional.py", line 48, in __get__
    res = instance.__dict__[self.name] = self.func(instance)
  File "/usr/local/lib/python3.7/site-packages/django/urls/resolvers.py", line 595, in urlconf_module
    return import_module(self.urlconf_name)
  File "/usr/local/lib/python3.7/importlib/__init__.py", line 127, in import_module
    return _bootstrap._gcd_import(name[level:], package, level)
  File "<frozen importlib._bootstrap>", line 1006, in _gcd_import
  File "<frozen importlib._bootstrap>", line 983, in _find_and_load
  File "<frozen importlib._bootstrap>", line 967, in _find_and_load_unlocked
  File "<frozen importlib._bootstrap>", line 677, in _load_unlocked
  File "<frozen importlib._bootstrap_external>", line 728, in exec_module
  File "<frozen importlib._bootstrap>", line 219, in _call_with_frames_removed
  File "./mainproject/urls.py", line 21, in <module>
    path('app/', include('app.urls')),
  File "/usr/local/lib/python3.7/site-packages/django/urls/conf.py", line 34, in include
    urlconf_module = import_module(urlconf_module)
  File "/usr/local/lib/python3.7/importlib/__init__.py", line 127, in import_module
    return _bootstrap._gcd_import(name[level:], package, level)
  File "<frozen importlib._bootstrap>", line 1006, in _gcd_import
  File "<frozen importlib._bootstrap>", line 983, in _find_and_load
  File "<frozen importlib._bootstrap>", line 967, in _find_and_load_unlocked
  File "<frozen importlib._bootstrap>", line 677, in _load_unlocked
  File "<frozen importlib._bootstrap_external>", line 728, in exec_module
  File "<frozen importlib._bootstrap>", line 219, in _call_with_frames_removed
  File "./app/urls.py", line 1, in <module>
    from djago.urls import path
ModuleNotFoundError: No module named 'djago'

During handling of the above exception, another exception occurred:

Traceback (most recent call last):
  File "/usr/local/lib/python3.7/site-packages/django/core/handlers/exception.py", line 47, in inner
    response = get_response(request)
  File "/usr/local/lib/python3.7/site-packages/django/utils/deprecation.py", line 117, in __call__
    response = response or self.get_response(request)
  File "/usr/local/lib/python3.7/site-packages/django/core/handlers/exception.py", line 49, in inner
    response = response_for_exception(request, exc)
  File "/usr/local/lib/python3.7/site-packages/django/core/handlers/exception.py", line 114, in response_for_exception
    response = handle_uncaught_exception(request, get_resolver(get_urlconf()), sys.exc_info())
  File "/usr/local/lib/python3.7/site-packages/django/core/handlers/exception.py", line 152, in handle_uncaught_exception
    callback = resolver.resolve_error_handler(500)
  File "/usr/local/lib/python3.7/site-packages/django/urls/resolvers.py", line 615, in resolve_error_handler
    callback = getattr(self.urlconf_module, 'handler%s' % view_type, None)
  File "/usr/local/lib/python3.7/site-packages/django/utils/functional.py", line 48, in __get__
    res = instance.__dict__[self.name] = self.func(instance)
  File "/usr/local/lib/python3.7/site-packages/django/urls/resolvers.py", line 595, in urlconf_module
    return import_module(self.urlconf_name)
  File "/usr/local/lib/python3.7/importlib/__init__.py", line 127, in import_module
    return _bootstrap._gcd_import(name[level:], package, level)
  File "<frozen importlib._bootstrap>", line 1006, in _gcd_import
  File "<frozen importlib._bootstrap>", line 983, in _find_and_load
  File "<frozen importlib._bootstrap>", line 967, in _find_and_load_unlocked
  File "<frozen importlib._bootstrap>", line 677, in _load_unlocked
  File "<frozen importlib._bootstrap_external>", line 728, in exec_module
  File "<frozen importlib._bootstrap>", line 219, in _call_with_frames_removed
  File "./mainproject/urls.py", line 21, in <module>
    path('app/', include('app.urls')),
  File "/usr/local/lib/python3.7/site-packages/django/urls/conf.py", line 34, in include
    urlconf_module = import_module(urlconf_module)
  File "/usr/local/lib/python3.7/importlib/__init__.py", line 127, in import_module
    return _bootstrap._gcd_import(name[level:], package, level)
  File "<frozen importlib._bootstrap>", line 1006, in _gcd_import
  File "<frozen importlib._bootstrap>", line 983, in _find_and_load
  File "<frozen importlib._bootstrap>", line 967, in _find_and_load_unlocked
  File "<frozen importlib._bootstrap>", line 677, in _load_unlocked
  File "<frozen importlib._bootstrap_external>", line 728, in exec_module
  File "<frozen importlib._bootstrap>", line 219, in _call_with_frames_removed
  File "./app/urls.py", line 1, in <module>
    from djago.urls import path
ModuleNotFoundError: No module named 'djago'

During handling of the above exception, another exception occurred:

Traceback (most recent call last):
  File "/usr/local/lib/python3.7/site-packages/django/core/handlers/exception.py", line 47, in inner
    response = get_response(request)
  File "/usr/local/lib/python3.7/site-packages/django/utils/deprecation.py", line 117, in __call__
    response = response or self.get_response(request)
  File "/usr/local/lib/python3.7/site-packages/django/core/handlers/exception.py", line 49, in inner
    response = response_for_exception(request, exc)
  File "/usr/local/lib/python3.7/site-packages/django/core/handlers/exception.py", line 114, in response_for_exception
    response = handle_uncaught_exception(request, get_resolver(get_urlconf()), sys.exc_info())
  File "/usr/local/lib/python3.7/site-packages/django/core/handlers/exception.py", line 152, in handle_uncaught_exception
    callback = resolver.resolve_error_handler(500)
  File "/usr/local/lib/python3.7/site-packages/django/urls/resolvers.py", line 615, in resolve_error_handler
    callback = getattr(self.urlconf_module, 'handler%s' % view_type, None)
  File "/usr/local/lib/python3.7/site-packages/django/utils/functional.py", line 48, in __get__
    res = instance.__dict__[self.name] = self.func(instance)
  File "/usr/local/lib/python3.7/site-packages/django/urls/resolvers.py", line 595, in urlconf_module
    return import_module(self.urlconf_name)
  File "/usr/local/lib/python3.7/importlib/__init__.py", line 127, in import_module
    return _bootstrap._gcd_import(name[level:], package, level)
  File "<frozen importlib._bootstrap>", line 1006, in _gcd_import
  File "<frozen importlib._bootstrap>", line 983, in _find_and_load
  File "<frozen importlib._bootstrap>", line 967, in _find_and_load_unlocked
  File "<frozen importlib._bootstrap>", line 677, in _load_unlocked
  File "<frozen importlib._bootstrap_external>", line 728, in exec_module
  File "<frozen importlib._bootstrap>", line 219, in _call_with_frames_removed
  File "./mainproject/urls.py", line 21, in <module>
    path('app/', include('app.urls')),
  File "/usr/local/lib/python3.7/site-packages/django/urls/conf.py", line 34, in include
    urlconf_module = import_module(urlconf_module)
  File "/usr/local/lib/python3.7/importlib/__init__.py", line 127, in import_module
    return _bootstrap._gcd_import(name[level:], package, level)
  File "<frozen importlib._bootstrap>", line 1006, in _gcd_import
  File "<frozen importlib._bootstrap>", line 983, in _find_and_load
  File "<frozen importlib._bootstrap>", line 967, in _find_and_load_unlocked
  File "<frozen importlib._bootstrap>", line 677, in _load_unlocked
  File "<frozen importlib._bootstrap_external>", line 728, in exec_module
  File "<frozen importlib._bootstrap>", line 219, in _call_with_frames_removed
  File "./app/urls.py", line 1, in <module>
    from djago.urls import path
ModuleNotFoundError: No module named 'djago'

During handling of the above exception, another exception occurred:

Traceback (most recent call last):
  File "/usr/local/lib/python3.7/site-packages/django/core/handlers/exception.py", line 47, in inner
    response = get_response(request)
  File "/usr/local/lib/python3.7/site-packages/django/utils/deprecation.py", line 117, in __call__
    response = response or self.get_response(request)
  File "/usr/local/lib/python3.7/site-packages/django/core/handlers/exception.py", line 49, in inner
    response = response_for_exception(request, exc)
  File "/usr/local/lib/python3.7/site-packages/django/core/handlers/exception.py", line 114, in response_for_exception
    response = handle_uncaught_exception(request, get_resolver(get_urlconf()), sys.exc_info())
  File "/usr/local/lib/python3.7/site-packages/django/core/handlers/exception.py", line 152, in handle_uncaught_exception
    callback = resolver.resolve_error_handler(500)
  File "/usr/local/lib/python3.7/site-packages/django/urls/resolvers.py", line 615, in resolve_error_handler
    callback = getattr(self.urlconf_module, 'handler%s' % view_type, None)
  File "/usr/local/lib/python3.7/site-packages/django/utils/functional.py", line 48, in __get__
    res = instance.__dict__[self.name] = self.func(instance)
  File "/usr/local/lib/python3.7/site-packages/django/urls/resolvers.py", line 595, in urlconf_module
    return import_module(self.urlconf_name)
  File "/usr/local/lib/python3.7/importlib/__init__.py", line 127, in import_module
    return _bootstrap._gcd_import(name[level:], package, level)
  File "<frozen importlib._bootstrap>", line 1006, in _gcd_import
  File "<frozen importlib._bootstrap>", line 983, in _find_and_load
  File "<frozen importlib._bootstrap>", line 967, in _find_and_load_unlocked
  File "<frozen importlib._bootstrap>", line 677, in _load_unlocked
  File "<frozen importlib._bootstrap_external>", line 728, in exec_module
  File "<frozen importlib._bootstrap>", line 219, in _call_with_frames_removed
  File "./mainproject/urls.py", line 21, in <module>
    path('app/', include('app.urls')),
  File "/usr/local/lib/python3.7/site-packages/django/urls/conf.py", line 34, in include
    urlconf_module = import_module(urlconf_module)
  File "/usr/local/lib/python3.7/importlib/__init__.py", line 127, in import_module
    return _bootstrap._gcd_import(name[level:], package, level)
  File "<frozen importlib._bootstrap>", line 1006, in _gcd_import
  File "<frozen importlib._bootstrap>", line 983, in _find_and_load
  File "<frozen importlib._bootstrap>", line 967, in _find_and_load_unlocked
  File "<frozen importlib._bootstrap>", line 677, in _load_unlocked
  File "<frozen importlib._bootstrap_external>", line 728, in exec_module
  File "<frozen importlib._bootstrap>", line 219, in _call_with_frames_removed
  File "./app/urls.py", line 1, in <module>
    from djago.urls import path
ModuleNotFoundError: No module named 'djago'

During handling of the above exception, another exception occurred:

Traceback (most recent call last):
  File "/usr/local/lib/python3.7/site-packages/django/core/handlers/exception.py", line 47, in inner
    response = get_response(request)
  File "/usr/local/lib/python3.7/site-packages/django/utils/deprecation.py", line 117, in __call__
    response = response or self.get_response(request)
  File "/usr/local/lib/python3.7/site-packages/django/core/handlers/exception.py", line 49, in inner
    response = response_for_exception(request, exc)
  File "/usr/local/lib/python3.7/site-packages/django/core/handlers/exception.py", line 114, in response_for_exception
    response = handle_uncaught_exception(request, get_resolver(get_urlconf()), sys.exc_info())
  File "/usr/local/lib/python3.7/site-packages/django/core/handlers/exception.py", line 152, in handle_uncaught_exception
    callback = resolver.resolve_error_handler(500)
  File "/usr/local/lib/python3.7/site-packages/django/urls/resolvers.py", line 615, in resolve_error_handler
    callback = getattr(self.urlconf_module, 'handler%s' % view_type, None)
  File "/usr/local/lib/python3.7/site-packages/django/utils/functional.py", line 48, in __get__
    res = instance.__dict__[self.name] = self.func(instance)
  File "/usr/local/lib/python3.7/site-packages/django/urls/resolvers.py", line 595, in urlconf_module
    return import_module(self.urlconf_name)
  File "/usr/local/lib/python3.7/importlib/__init__.py", line 127, in import_module
    return _bootstrap._gcd_import(name[level:], package, level)
  File "<frozen importlib._bootstrap>", line 1006, in _gcd_import
  File "<frozen importlib._bootstrap>", line 983, in _find_and_load
  File "<frozen importlib._bootstrap>", line 967, in _find_and_load_unlocked
  File "<frozen importlib._bootstrap>", line 677, in _load_unlocked
  File "<frozen importlib._bootstrap_external>", line 728, in exec_module
  File "<frozen importlib._bootstrap>", line 219, in _call_with_frames_removed
  File "./mainproject/urls.py", line 21, in <module>
    path('app/', include('app.urls')),
  File "/usr/local/lib/python3.7/site-packages/django/urls/conf.py", line 34, in include
    urlconf_module = import_module(urlconf_module)
  File "/usr/local/lib/python3.7/importlib/__init__.py", line 127, in import_module
    return _bootstrap._gcd_import(name[level:], package, level)
  File "<frozen importlib._bootstrap>", line 1006, in _gcd_import
  File "<frozen importlib._bootstrap>", line 983, in _find_and_load
  File "<frozen importlib._bootstrap>", line 967, in _find_and_load_unlocked
  File "<frozen importlib._bootstrap>", line 677, in _load_unlocked
  File "<frozen importlib._bootstrap_external>", line 728, in exec_module
  File "<frozen importlib._bootstrap>", line 219, in _call_with_frames_removed
  File "./app/urls.py", line 1, in <module>
    from djago.urls import path
ModuleNotFoundError: No module named 'djago'

During handling of the above exception, another exception occurred:

Traceback (most recent call last):
  File "/usr/local/lib/python3.7/site-packages/django/core/handlers/exception.py", line 47, in inner
    response = get_response(request)
  File "/usr/local/lib/python3.7/site-packages/django/utils/deprecation.py", line 117, in __call__
    response = response or self.get_response(request)
  File "/usr/local/lib/python3.7/site-packages/django/core/handlers/exception.py", line 49, in inner
    response = response_for_exception(request, exc)
  File "/usr/local/lib/python3.7/site-packages/django/core/handlers/exception.py", line 114, in response_for_exception
    response = handle_uncaught_exception(request, get_resolver(get_urlconf()), sys.exc_info())
  File "/usr/local/lib/python3.7/site-packages/django/core/handlers/exception.py", line 152, in handle_uncaught_exception
    callback = resolver.resolve_error_handler(500)
  File "/usr/local/lib/python3.7/site-packages/django/urls/resolvers.py", line 615, in resolve_error_handler
    callback = getattr(self.urlconf_module, 'handler%s' % view_type, None)
  File "/usr/local/lib/python3.7/site-packages/django/utils/functional.py", line 48, in __get__
    res = instance.__dict__[self.name] = self.func(instance)
  File "/usr/local/lib/python3.7/site-packages/django/urls/resolvers.py", line 595, in urlconf_module
    return import_module(self.urlconf_name)
  File "/usr/local/lib/python3.7/importlib/__init__.py", line 127, in import_module
    return _bootstrap._gcd_import(name[level:], package, level)
  File "<frozen importlib._bootstrap>", line 1006, in _gcd_import
  File "<frozen importlib._bootstrap>", line 983, in _find_and_load
  File "<frozen importlib._bootstrap>", line 967, in _find_and_load_unlocked
  File "<frozen importlib._bootstrap>", line 677, in _load_unlocked
  File "<frozen importlib._bootstrap_external>", line 728, in exec_module
  File "<frozen importlib._bootstrap>", line 219, in _call_with_frames_removed
  File "./mainproject/urls.py", line 21, in <module>
    path('app/', include('app.urls')),
  File "/usr/local/lib/python3.7/site-packages/django/urls/conf.py", line 34, in include
    urlconf_module = import_module(urlconf_module)
  File "/usr/local/lib/python3.7/importlib/__init__.py", line 127, in import_module
    return _bootstrap._gcd_import(name[level:], package, level)
  File "<frozen importlib._bootstrap>", line 1006, in _gcd_import
  File "<frozen importlib._bootstrap>", line 983, in _find_and_load
  File "<frozen importlib._bootstrap>", line 967, in _find_and_load_unlocked
  File "<frozen importlib._bootstrap>", line 677, in _load_unlocked
  File "<frozen importlib._bootstrap_external>", line 728, in exec_module
  File "<frozen importlib._bootstrap>", line 219, in _call_with_frames_removed
  File "./app/urls.py", line 1, in <module>
    from djago.urls import path
ModuleNotFoundError: No module named 'djago'

During handling of the above exception, another exception occurred:

Traceback (most recent call last):
  File "/usr/local/lib/python3.7/site-packages/django/core/handlers/exception.py", line 47, in inner
    response = get_response(request)
  File "/usr/local/lib/python3.7/site-packages/django/utils/deprecation.py", line 117, in __call__
    response = response or self.get_response(request)
  File "/usr/local/lib/python3.7/site-packages/django/core/handlers/exception.py", line 49, in inner
    response = response_for_exception(request, exc)
  File "/usr/local/lib/python3.7/site-packages/django/core/handlers/exception.py", line 114, in response_for_exception
    response = handle_uncaught_exception(request, get_resolver(get_urlconf()), sys.exc_info())
  File "/usr/local/lib/python3.7/site-packages/django/core/handlers/exception.py", line 152, in handle_uncaught_exception
    callback = resolver.resolve_error_handler(500)
  File "/usr/local/lib/python3.7/site-packages/django/urls/resolvers.py", line 615, in resolve_error_handler
    callback = getattr(self.urlconf_module, 'handler%s' % view_type, None)
  File "/usr/local/lib/python3.7/site-packages/django/utils/functional.py", line 48, in __get__
    res = instance.__dict__[self.name] = self.func(instance)
  File "/usr/local/lib/python3.7/site-packages/django/urls/resolvers.py", line 595, in urlconf_module
    return import_module(self.urlconf_name)
  File "/usr/local/lib/python3.7/importlib/__init__.py", line 127, in import_module
    return _bootstrap._gcd_import(name[level:], package, level)
  File "<frozen importlib._bootstrap>", line 1006, in _gcd_import
  File "<frozen importlib._bootstrap>", line 983, in _find_and_load
  File "<frozen importlib._bootstrap>", line 967, in _find_and_load_unlocked
  File "<frozen importlib._bootstrap>", line 677, in _load_unlocked
  File "<frozen importlib._bootstrap_external>", line 728, in exec_module
  File "<frozen importlib._bootstrap>", line 219, in _call_with_frames_removed
  File "./mainproject/urls.py", line 21, in <module>
    path('app/', include('app.urls')),
  File "/usr/local/lib/python3.7/site-packages/django/urls/conf.py", line 34, in include
    urlconf_module = import_module(urlconf_module)
  File "/usr/local/lib/python3.7/importlib/__init__.py", line 127, in import_module
    return _bootstrap._gcd_import(name[level:], package, level)
  File "<frozen importlib._bootstrap>", line 1006, in _gcd_import
  File "<frozen importlib._bootstrap>", line 983, in _find_and_load
  File "<frozen importlib._bootstrap>", line 967, in _find_and_load_unlocked
  File "<frozen importlib._bootstrap>", line 677, in _load_unlocked
  File "<frozen importlib._bootstrap_external>", line 728, in exec_module
  File "<frozen importlib._bootstrap>", line 219, in _call_with_frames_removed
  File "./app/urls.py", line 1, in <module>
    from djago.urls import path
ModuleNotFoundError: No module named 'djago'

During handling of the above exception, another exception occurred:

Traceback (most recent call last):
  File "/usr/local/lib/python3.7/site-packages/django/core/handlers/exception.py", line 47, in inner
    response = get_response(request)
  File "/usr/local/lib/python3.7/site-packages/django/utils/deprecation.py", line 117, in __call__
    response = response or self.get_response(request)
  File "/usr/local/lib/python3.7/site-packages/django/core/handlers/exception.py", line 49, in inner
    response = response_for_exception(request, exc)
  File "/usr/local/lib/python3.7/site-packages/django/core/handlers/exception.py", line 114, in response_for_exception
    response = handle_uncaught_exception(request, get_resolver(get_urlconf()), sys.exc_info())
  File "/usr/local/lib/python3.7/site-packages/django/core/handlers/exception.py", line 152, in handle_uncaught_exception
    callback = resolver.resolve_error_handler(500)
  File "/usr/local/lib/python3.7/site-packages/django/urls/resolvers.py", line 615, in resolve_error_handler
    callback = getattr(self.urlconf_module, 'handler%s' % view_type, None)
  File "/usr/local/lib/python3.7/site-packages/django/utils/functional.py", line 48, in __get__
    res = instance.__dict__[self.name] = self.func(instance)
  File "/usr/local/lib/python3.7/site-packages/django/urls/resolvers.py", line 595, in urlconf_module
    return import_module(self.urlconf_name)
  File "/usr/local/lib/python3.7/importlib/__init__.py", line 127, in import_module
    return _bootstrap._gcd_import(name[level:], package, level)
  File "<frozen importlib._bootstrap>", line 1006, in _gcd_import
  File "<frozen importlib._bootstrap>", line 983, in _find_and_load
  File "<frozen importlib._bootstrap>", line 967, in _find_and_load_unlocked
  File "<frozen importlib._bootstrap>", line 677, in _load_unlocked
  File "<frozen importlib._bootstrap_external>", line 728, in exec_module
  File "<frozen importlib._bootstrap>", line 219, in _call_with_frames_removed
  File "./mainproject/urls.py", line 21, in <module>
    path('app/', include('app.urls')),
  File "/usr/local/lib/python3.7/site-packages/django/urls/conf.py", line 34, in include
    urlconf_module = import_module(urlconf_module)
  File "/usr/local/lib/python3.7/importlib/__init__.py", line 127, in import_module
    return _bootstrap._gcd_import(name[level:], package, level)
  File "<frozen importlib._bootstrap>", line 1006, in _gcd_import
  File "<frozen importlib._bootstrap>", line 983, in _find_and_load
  File "<frozen importlib._bootstrap>", line 967, in _find_and_load_unlocked
  File "<frozen importlib._bootstrap>", line 677, in _load_unlocked
  File "<frozen importlib._bootstrap_external>", line 728, in exec_module
  File "<frozen importlib._bootstrap>", line 219, in _call_with_frames_removed
  File "./app/urls.py", line 1, in <module>
    from djago.urls import path
ModuleNotFoundError: No module named 'djago'

During handling of the above exception, another exception occurred:

Traceback (most recent call last):
  File "/usr/local/lib/python3.7/site-packages/django/core/handlers/wsgi.py", line 133, in __call__
    response = self.get_response(request)
  File "/usr/local/lib/python3.7/site-packages/django/core/handlers/base.py", line 130, in get_response
    response = self._middleware_chain(request)
  File "/usr/local/lib/python3.7/site-packages/django/core/handlers/exception.py", line 49, in inner
    response = response_for_exception(request, exc)
  File "/usr/local/lib/python3.7/site-packages/django/core/handlers/exception.py", line 114, in response_for_exception
    response = handle_uncaught_exception(request, get_resolver(get_urlconf()), sys.exc_info())
  File "/usr/local/lib/python3.7/site-packages/django/core/handlers/exception.py", line 152, in handle_uncaught_exception
    callback = resolver.resolve_error_handler(500)
  File "/usr/local/lib/python3.7/site-packages/django/urls/resolvers.py", line 615, in resolve_error_handler
    callback = getattr(self.urlconf_module, 'handler%s' % view_type, None)
  File "/usr/local/lib/python3.7/site-packages/django/utils/functional.py", line 48, in __get__
    res = instance.__dict__[self.name] = self.func(instance)
  File "/usr/local/lib/python3.7/site-packages/django/urls/resolvers.py", line 595, in urlconf_module
    return import_module(self.urlconf_name)
  File "/usr/local/lib/python3.7/importlib/__init__.py", line 127, in import_module
    return _bootstrap._gcd_import(name[level:], package, level)
  File "<frozen importlib._bootstrap>", line 1006, in _gcd_import
  File "<frozen importlib._bootstrap>", line 983, in _find_and_load
  File "<frozen importlib._bootstrap>", line 967, in _find_and_load_unlocked
  File "<frozen importlib._bootstrap>", line 677, in _load_unlocked
  File "<frozen importlib._bootstrap_external>", line 728, in exec_module
  File "<frozen importlib._bootstrap>", line 219, in _call_with_frames_removed
  File "./mainproject/urls.py", line 21, in <module>
    path('app/', include('app.urls')),
  File "/usr/local/lib/python3.7/site-packages/django/urls/conf.py", line 34, in include
    urlconf_module = import_module(urlconf_module)
  File "/usr/local/lib/python3.7/importlib/__init__.py", line 127, in import_module
    return _bootstrap._gcd_import(name[level:], package, level)
  File "<frozen importlib._bootstrap>", line 1006, in _gcd_import
  File "<frozen importlib._bootstrap>", line 983, in _find_and_load
  File "<frozen importlib._bootstrap>", line 967, in _find_and_load_unlocked
  File "<frozen importlib._bootstrap>", line 677, in _load_unlocked
  File "<frozen importlib._bootstrap_external>", line 728, in exec_module
  File "<frozen importlib._bootstrap>", line 219, in _call_with_frames_removed
  File "./app/urls.py", line 1, in <module>
    from djago.urls import path
ModuleNotFoundError: No module named 'djago'
[pid: 11|app: 0|req: 1/1] 172.20.0.1 () {56 vars in 1004 bytes} [Sun Aug 10 11:02:05 2025] GET / => generated 0 bytes in 56 msecs (HTTP/1.1 500) 0 headers in 0 bytes (0 switches on core 0)
[uwsgi-python-reloader] module/file ./mainproject/settings.py has been modified
...gracefully killing workers...
Gracefully killing worker 1 (pid: 11)...
worker 1 buried after 1 seconds
binary reloading uWSGI...
chdir() to /code
closing all non-uwsgi socket fds > 2 (max_fd = 1024)...
found fd 3 mapped to socket 0 (:8001)
running /usr/local/bin/uwsgi
[uWSGI] getting INI configuration from /code/mainproject/django.ini
*** Starting uWSGI 2.0.30 (64bit) on [Sun Aug 10 11:02:23 2025] ***
compiled with version: 12.2.0 on 10 August 2025 08:55:24
os: Linux-5.15.167.4-microsoft-standard-WSL2 #1 SMP Tue Nov 5 00:21:55 UTC 2024
nodename: c59b46171162
machine: x86_64
clock source: unix
pcre jit disabled
detected number of CPU cores: 8
current working directory: /code
detected binary path: /usr/local/bin/uwsgi
uWSGI running as root, you can use --uid/--gid/--chroot options
*** WARNING: you are running uWSGI as root !!! (use the --uid flag) *** 
your memory page size is 4096 bytes
detected max file descriptor number: 1024
lock engine: pthread robust mutexes
thunder lock: disabled (you can enable it with --thunder-lock)
uwsgi socket 0 inherited INET address :8001 fd 3
uWSGI running as root, you can use --uid/--gid/--chroot options
*** WARNING: you are running uWSGI as root !!! (use the --uid flag) *** 
Python version: 3.7.17 (default, Sep 20 2023, 11:53:41)  [GCC 12.2.0]
Python main interpreter initialized at 0x55fdcd07c130
uWSGI running as root, you can use --uid/--gid/--chroot options
*** WARNING: you are running uWSGI as root !!! (use the --uid flag) *** 
python threads support enabled
your server socket listen backlog is limited to 100 connections
your mercy for graceful operations on workers is 60 seconds
mapped 145840 bytes (142 KB) for 1 cores
*** Operational MODE: single process ***
WSGI app 0 (mountpoint='') ready in 1 seconds on interpreter 0x55fdcd07c130 pid: 1 (default app)
mountpoint  already configured. skip.
uWSGI running as root, you can use --uid/--gid/--chroot options
*** WARNING: you are running uWSGI as root !!! (use the --uid flag) *** 
*** uWSGI is running in multiple interpreter mode ***
gracefully (RE)spawned uWSGI master process (pid: 1)
spawned uWSGI worker 1 (pid: 13, cores: 1)
Python auto-reloader enabled
Internal Server Error: /
Traceback (most recent call last):
  File "/usr/local/lib/python3.7/site-packages/django/core/handlers/exception.py", line 47, in inner
    response = get_response(request)
  File "/usr/local/lib/python3.7/site-packages/django/core/handlers/base.py", line 167, in _get_response
    callback, callback_args, callback_kwargs = self.resolve_request(request)
  File "/usr/local/lib/python3.7/site-packages/django/core/handlers/base.py", line 290, in resolve_request
    resolver_match = resolver.resolve(request.path_info)
  File "/usr/local/lib/python3.7/site-packages/django/urls/resolvers.py", line 560, in resolve
    for pattern in self.url_patterns:
  File "/usr/local/lib/python3.7/site-packages/django/utils/functional.py", line 48, in __get__
    res = instance.__dict__[self.name] = self.func(instance)
  File "/usr/local/lib/python3.7/site-packages/django/urls/resolvers.py", line 602, in url_patterns
    patterns = getattr(self.urlconf_module, "urlpatterns", self.urlconf_module)
  File "/usr/local/lib/python3.7/site-packages/django/utils/functional.py", line 48, in __get__
    res = instance.__dict__[self.name] = self.func(instance)
  File "/usr/local/lib/python3.7/site-packages/django/urls/resolvers.py", line 595, in urlconf_module
    return import_module(self.urlconf_name)
  File "/usr/local/lib/python3.7/importlib/__init__.py", line 127, in import_module
    return _bootstrap._gcd_import(name[level:], package, level)
  File "<frozen importlib._bootstrap>", line 1006, in _gcd_import
  File "<frozen importlib._bootstrap>", line 983, in _find_and_load
  File "<frozen importlib._bootstrap>", line 967, in _find_and_load_unlocked
  File "<frozen importlib._bootstrap>", line 677, in _load_unlocked
  File "<frozen importlib._bootstrap_external>", line 728, in exec_module
  File "<frozen importlib._bootstrap>", line 219, in _call_with_frames_removed
  File "./mainproject/urls.py", line 21, in <module>
    path('app/', include('app.urls')),
  File "/usr/local/lib/python3.7/site-packages/django/urls/conf.py", line 34, in include
    urlconf_module = import_module(urlconf_module)
  File "/usr/local/lib/python3.7/importlib/__init__.py", line 127, in import_module
    return _bootstrap._gcd_import(name[level:], package, level)
  File "<frozen importlib._bootstrap>", line 1006, in _gcd_import
  File "<frozen importlib._bootstrap>", line 983, in _find_and_load
  File "<frozen importlib._bootstrap>", line 967, in _find_and_load_unlocked
  File "<frozen importlib._bootstrap>", line 677, in _load_unlocked
  File "<frozen importlib._bootstrap_external>", line 728, in exec_module
  File "<frozen importlib._bootstrap>", line 219, in _call_with_frames_removed
  File "./app/urls.py", line 1, in <module>
    from djago.urls import path
ModuleNotFoundError: No module named 'djago'
[pid: 13|app: 0|req: 1/1] 172.20.0.1 () {56 vars in 1004 bytes} [Sun Aug 10 11:02:26 2025] GET / => generated 142878 bytes in 93 msecs (HTTP/1.1 500) 6 headers in 187 bytes (1 switches on core 0)
Not Found: /
[pid: 13|app: 0|req: 2/2] 172.20.0.1 () {56 vars in 1004 bytes} [Sun Aug 10 11:02:52 2025] GET / => generated 2168 bytes in 17 msecs (HTTP/1.1 404) 5 headers in 159 bytes (1 switches on core 0)
[uwsgi-python-reloader] module/file ./mainproject/urls.py has been modified
...gracefully killing workers...
Gracefully killing worker 1 (pid: 13)...
worker 1 buried after 1 seconds
binary reloading uWSGI...
chdir() to /code
closing all non-uwsgi socket fds > 2 (max_fd = 1024)...
found fd 3 mapped to socket 0 (:8001)
running /usr/local/bin/uwsgi
[uWSGI] getting INI configuration from /code/mainproject/django.ini
*** Starting uWSGI 2.0.30 (64bit) on [Sun Aug 10 11:04:03 2025] ***
compiled with version: 12.2.0 on 10 August 2025 08:55:24
os: Linux-5.15.167.4-microsoft-standard-WSL2 #1 SMP Tue Nov 5 00:21:55 UTC 2024
nodename: c59b46171162
machine: x86_64
clock source: unix
pcre jit disabled
detected number of CPU cores: 8
current working directory: /code
detected binary path: /usr/local/bin/uwsgi
uWSGI running as root, you can use --uid/--gid/--chroot options
*** WARNING: you are running uWSGI as root !!! (use the --uid flag) *** 
your memory page size is 4096 bytes
detected max file descriptor number: 1024
lock engine: pthread robust mutexes
thunder lock: disabled (you can enable it with --thunder-lock)
uwsgi socket 0 inherited INET address :8001 fd 3
uWSGI running as root, you can use --uid/--gid/--chroot options
*** WARNING: you are running uWSGI as root !!! (use the --uid flag) *** 
Python version: 3.7.17 (default, Sep 20 2023, 11:53:41)  [GCC 12.2.0]
Python main interpreter initialized at 0x55ddaedb4130
uWSGI running as root, you can use --uid/--gid/--chroot options
*** WARNING: you are running uWSGI as root !!! (use the --uid flag) *** 
python threads support enabled
your server socket listen backlog is limited to 100 connections
your mercy for graceful operations on workers is 60 seconds
mapped 145840 bytes (142 KB) for 1 cores
*** Operational MODE: single process ***
WSGI app 0 (mountpoint='') ready in 1 seconds on interpreter 0x55ddaedb4130 pid: 1 (default app)
mountpoint  already configured. skip.
uWSGI running as root, you can use --uid/--gid/--chroot options
*** WARNING: you are running uWSGI as root !!! (use the --uid flag) *** 
*** uWSGI is running in multiple interpreter mode ***
gracefully (RE)spawned uWSGI master process (pid: 1)
spawned uWSGI worker 1 (pid: 15, cores: 1)
Python auto-reloader enabled
Not Found: /
[pid: 15|app: 0|req: 1/1] 172.20.0.1 () {56 vars in 1004 bytes} [Sun Aug 10 11:04:20 2025] GET / => generated 2168 bytes in 37 msecs (HTTP/1.1 404) 5 headers in 159 bytes (1 switches on core 0)
Not Found: /
[pid: 15|app: 0|req: 2/2] 172.20.0.1 () {56 vars in 1004 bytes} [Sun Aug 10 11:04:22 2025] GET / => generated 2168 bytes in 14 msecs (HTTP/1.1 404) 5 headers in 159 bytes (1 switches on core 0)
[uwsgi-python-reloader] module/file ./app/views.py has been modified
...gracefully killing workers...
Gracefully killing worker 1 (pid: 15)...
worker 1 buried after 1 seconds
binary reloading uWSGI...
chdir() to /code
closing all non-uwsgi socket fds > 2 (max_fd = 1024)...
found fd 3 mapped to socket 0 (:8001)
running /usr/local/bin/uwsgi
[uWSGI] getting INI configuration from /code/mainproject/django.ini
*** Starting uWSGI 2.0.30 (64bit) on [Sun Aug 10 11:05:04 2025] ***
compiled with version: 12.2.0 on 10 August 2025 08:55:24
os: Linux-5.15.167.4-microsoft-standard-WSL2 #1 SMP Tue Nov 5 00:21:55 UTC 2024
nodename: c59b46171162
machine: x86_64
clock source: unix
pcre jit disabled
detected number of CPU cores: 8
current working directory: /code
detected binary path: /usr/local/bin/uwsgi
uWSGI running as root, you can use --uid/--gid/--chroot options
*** WARNING: you are running uWSGI as root !!! (use the --uid flag) *** 
your memory page size is 4096 bytes
detected max file descriptor number: 1024
lock engine: pthread robust mutexes
thunder lock: disabled (you can enable it with --thunder-lock)
uwsgi socket 0 inherited INET address :8001 fd 3
uWSGI running as root, you can use --uid/--gid/--chroot options
*** WARNING: you are running uWSGI as root !!! (use the --uid flag) *** 
Python version: 3.7.17 (default, Sep 20 2023, 11:53:41)  [GCC 12.2.0]
Python main interpreter initialized at 0x55ca52c90130
uWSGI running as root, you can use --uid/--gid/--chroot options
*** WARNING: you are running uWSGI as root !!! (use the --uid flag) *** 
python threads support enabled
your server socket listen backlog is limited to 100 connections
your mercy for graceful operations on workers is 60 seconds
mapped 145840 bytes (142 KB) for 1 cores
*** Operational MODE: single process ***
WSGI app 0 (mountpoint='') ready in 1 seconds on interpreter 0x55ca52c90130 pid: 1 (default app)
mountpoint  already configured. skip.
uWSGI running as root, you can use --uid/--gid/--chroot options
*** WARNING: you are running uWSGI as root !!! (use the --uid flag) *** 
*** uWSGI is running in multiple interpreter mode ***
gracefully (RE)spawned uWSGI master process (pid: 1)
spawned uWSGI worker 1 (pid: 17, cores: 1)
Python auto-reloader enabled
Not Found: /
[pid: 17|app: 0|req: 1/1] 172.20.0.1 () {56 vars in 1004 bytes} [Sun Aug 10 11:05:09 2025] GET / => generated 2168 bytes in 42 msecs (HTTP/1.1 404) 5 headers in 159 bytes (1 switches on core 0)
Not Found: /
[pid: 17|app: 0|req: 2/2] 172.20.0.1 () {56 vars in 1004 bytes} [Sun Aug 10 11:05:11 2025] GET / => generated 2168 bytes in 5 msecs (HTTP/1.1 404) 5 headers in 159 bytes (1 switches on core 0)
Not Found: /
[pid: 17|app: 0|req: 3/3] 172.20.0.1 () {56 vars in 1004 bytes} [Sun Aug 10 11:05:12 2025] GET / => generated 2168 bytes in 7 msecs (HTTP/1.1 404) 5 headers in 159 bytes (1 switches on core 0)
Not Found: /
[pid: 17|app: 0|req: 4/4] 172.20.0.1 () {56 vars in 1004 bytes} [Sun Aug 10 11:05:12 2025] GET / => generated 2168 bytes in 7 msecs (HTTP/1.1 404) 5 headers in 159 bytes (1 switches on core 0)
Not Found: /
[pid: 17|app: 0|req: 5/5] 172.20.0.1 () {56 vars in 1004 bytes} [Sun Aug 10 11:05:12 2025] GET / => generated 2168 bytes in 5 msecs (HTTP/1.1 404) 5 headers in 159 bytes (1 switches on core 0)
Not Found: /
[pid: 17|app: 0|req: 6/6] 172.20.0.1 () {56 vars in 1004 bytes} [Sun Aug 10 11:05:13 2025] GET / => generated 2168 bytes in 6 msecs (HTTP/1.1 404) 5 headers in 159 bytes (1 switches on core 0)
Not Found: /
[pid: 17|app: 0|req: 7/7] 172.20.0.1 () {56 vars in 1004 bytes} [Sun Aug 10 11:05:13 2025] GET / => generated 2168 bytes in 6 msecs (HTTP/1.1 404) 5 headers in 159 bytes (1 switches on core 0)
Not Found: /
[pid: 17|app: 0|req: 8/8] 172.20.0.1 () {54 vars in 973 bytes} [Sun Aug 10 11:05:26 2025] GET / => generated 2168 bytes in 5 msecs (HTTP/1.1 404) 5 headers in 159 bytes (1 switches on core 0)
[pid: 17|app: 0|req: 9/9] 172.20.0.1 () {54 vars in 979 bytes} [Sun Aug 10 11:09:53 2025] GET /app => generated 0 bytes in 80 msecs (HTTP/1.1 301) 5 headers in 173 bytes (1 switches on core 0)
[pid: 17|app: 0|req: 10/10] 172.20.0.1 () {54 vars in 981 bytes} [Sun Aug 10 11:09:53 2025] GET /app/ => generated 37 bytes in 13 msecs (HTTP/1.1 200) 5 headers in 165 bytes (1 switches on core 0)
[uwsgi-python-reloader] module/file ./mainproject/settings.py has been modified
...gracefully killing workers...
Gracefully killing worker 1 (pid: 17)...
worker 1 buried after 2 seconds
binary reloading uWSGI...
chdir() to /code
closing all non-uwsgi socket fds > 2 (max_fd = 1024)...
found fd 3 mapped to socket 0 (:8001)
running /usr/local/bin/uwsgi
[uWSGI] getting INI configuration from /code/mainproject/django.ini
*** Starting uWSGI 2.0.30 (64bit) on [Sun Aug 10 11:14:22 2025] ***
compiled with version: 12.2.0 on 10 August 2025 08:55:24
os: Linux-5.15.167.4-microsoft-standard-WSL2 #1 SMP Tue Nov 5 00:21:55 UTC 2024
nodename: c59b46171162
machine: x86_64
clock source: unix
pcre jit disabled
detected number of CPU cores: 8
current working directory: /code
detected binary path: /usr/local/bin/uwsgi
uWSGI running as root, you can use --uid/--gid/--chroot options
*** WARNING: you are running uWSGI as root !!! (use the --uid flag) *** 
your memory page size is 4096 bytes
detected max file descriptor number: 1024
lock engine: pthread robust mutexes
thunder lock: disabled (you can enable it with --thunder-lock)
uwsgi socket 0 inherited INET address :8001 fd 3
uWSGI running as root, you can use --uid/--gid/--chroot options
*** WARNING: you are running uWSGI as root !!! (use the --uid flag) *** 
Python version: 3.7.17 (default, Sep 20 2023, 11:53:41)  [GCC 12.2.0]
Python main interpreter initialized at 0x562210e99130
uWSGI running as root, you can use --uid/--gid/--chroot options
*** WARNING: you are running uWSGI as root !!! (use the --uid flag) *** 
python threads support enabled
your server socket listen backlog is limited to 100 connections
your mercy for graceful operations on workers is 60 seconds
mapped 145840 bytes (142 KB) for 1 cores
*** Operational MODE: single process ***
WSGI app 0 (mountpoint='') ready in 2 seconds on interpreter 0x562210e99130 pid: 1 (default app)
mountpoint  already configured. skip.
uWSGI running as root, you can use --uid/--gid/--chroot options
*** WARNING: you are running uWSGI as root !!! (use the --uid flag) *** 
*** uWSGI is running in multiple interpreter mode ***
gracefully (RE)spawned uWSGI master process (pid: 1)
spawned uWSGI worker 1 (pid: 19, cores: 1)
Python auto-reloader enabled
[uwsgi-python-reloader] module/file ./mainproject/settings.py has been modified
...gracefully killing workers...
Gracefully killing worker 1 (pid: 19)...
worker 1 buried after 1 seconds
binary reloading uWSGI...
chdir() to /code
closing all non-uwsgi socket fds > 2 (max_fd = 1024)...
found fd 3 mapped to socket 0 (:8001)
running /usr/local/bin/uwsgi
[uWSGI] getting INI configuration from /code/mainproject/django.ini
*** Starting uWSGI 2.0.30 (64bit) on [Sun Aug 10 11:14:48 2025] ***
compiled with version: 12.2.0 on 10 August 2025 08:55:24
os: Linux-5.15.167.4-microsoft-standard-WSL2 #1 SMP Tue Nov 5 00:21:55 UTC 2024
nodename: c59b46171162
machine: x86_64
clock source: unix
pcre jit disabled
detected number of CPU cores: 8
current working directory: /code
detected binary path: /usr/local/bin/uwsgi
uWSGI running as root, you can use --uid/--gid/--chroot options
*** WARNING: you are running uWSGI as root !!! (use the --uid flag) *** 
your memory page size is 4096 bytes
detected max file descriptor number: 1024
lock engine: pthread robust mutexes
thunder lock: disabled (you can enable it with --thunder-lock)
uwsgi socket 0 inherited INET address :8001 fd 3
uWSGI running as root, you can use --uid/--gid/--chroot options
*** WARNING: you are running uWSGI as root !!! (use the --uid flag) *** 
Python version: 3.7.17 (default, Sep 20 2023, 11:53:41)  [GCC 12.2.0]
Python main interpreter initialized at 0x55b183982130
uWSGI running as root, you can use --uid/--gid/--chroot options
*** WARNING: you are running uWSGI as root !!! (use the --uid flag) *** 
python threads support enabled
your server socket listen backlog is limited to 100 connections
your mercy for graceful operations on workers is 60 seconds
mapped 145840 bytes (142 KB) for 1 cores
*** Operational MODE: single process ***
WSGI app 0 (mountpoint='') ready in 0 seconds on interpreter 0x55b183982130 pid: 1 (default app)
mountpoint  already configured. skip.
uWSGI running as root, you can use --uid/--gid/--chroot options
*** WARNING: you are running uWSGI as root !!! (use the --uid flag) *** 
*** uWSGI is running in multiple interpreter mode ***
gracefully (RE)spawned uWSGI master process (pid: 1)
spawned uWSGI worker 1 (pid: 21, cores: 1)
Python auto-reloader enabled
[uwsgi-python-reloader] module/file ./app/models.py has been modified
...gracefully killing workers...
Gracefully killing worker 1 (pid: 21)...
worker 1 buried after 2 seconds
binary reloading uWSGI...
chdir() to /code
closing all non-uwsgi socket fds > 2 (max_fd = 1024)...
found fd 3 mapped to socket 0 (:8001)
running /usr/local/bin/uwsgi
[uWSGI] getting INI configuration from /code/mainproject/django.ini
*** Starting uWSGI 2.0.30 (64bit) on [Mon Aug 11 01:25:28 2025] ***
compiled with version: 12.2.0 on 10 August 2025 08:55:24
os: Linux-5.15.167.4-microsoft-standard-WSL2 #1 SMP Tue Nov 5 00:21:55 UTC 2024
nodename: c59b46171162
machine: x86_64
clock source: unix
pcre jit disabled
detected number of CPU cores: 8
current working directory: /code
detected binary path: /usr/local/bin/uwsgi
uWSGI running as root, you can use --uid/--gid/--chroot options
*** WARNING: you are running uWSGI as root !!! (use the --uid flag) *** 
your memory page size is 4096 bytes
detected max file descriptor number: 1024
lock engine: pthread robust mutexes
thunder lock: disabled (you can enable it with --thunder-lock)
uwsgi socket 0 inherited INET address :8001 fd 3
uWSGI running as root, you can use --uid/--gid/--chroot options
*** WARNING: you are running uWSGI as root !!! (use the --uid flag) *** 
Python version: 3.7.17 (default, Sep 20 2023, 11:53:41)  [GCC 12.2.0]
Python main interpreter initialized at 0x555d43c80130
uWSGI running as root, you can use --uid/--gid/--chroot options
*** WARNING: you are running uWSGI as root !!! (use the --uid flag) *** 
python threads support enabled
your server socket listen backlog is limited to 100 connections
your mercy for graceful operations on workers is 60 seconds
mapped 145840 bytes (142 KB) for 1 cores
*** Operational MODE: single process ***
WSGI app 0 (mountpoint='') ready in 1 seconds on interpreter 0x555d43c80130 pid: 1 (default app)
mountpoint  already configured. skip.
uWSGI running as root, you can use --uid/--gid/--chroot options
*** WARNING: you are running uWSGI as root !!! (use the --uid flag) *** 
*** uWSGI is running in multiple interpreter mode ***
gracefully (RE)spawned uWSGI master process (pid: 1)
spawned uWSGI worker 1 (pid: 23, cores: 1)
Python auto-reloader enabled
